Workbook

Sheet Huong dan
A1: Kế hoạch từng tuần — TACo-ISP (KV260), 65 tuần: 05/10/2026 – 02/01/2028
A3: Sheet TV1, TV2, TV3: kế hoạch riêng của từng sinh viên. Sheet 'Tong hop': cả nhóm theo tuần. Sheet 'Tien do': tự đếm theo trạng thái.
A4: Ô NỀN VÀNG là ô cần điền hằng tuần: cột Trạng thái (chọn từ danh sách) và Ghi chú. Các cột khác là kế hoạch gốc, không sửa.
A5: Ví dụ một dòng đã điền: Tuần 1 · Trạng thái = 'Xong' · Ghi chú = 'Vitis AI 3.0 docker chạy; image hash a1b2c3 ghi vào ENV.md'.
A6: Hàng nền xanh là tuần có cổng kiểm tra (G0–G6) hoặc nộp bài; tiêu chí cổng xem mục 7 của Đề cương.
A7: Họp nhóm thứ Hai hằng tuần: mỗi người cập nhật Trạng thái tuần vừa qua trước khi họp.
A9: Vai trò
A10: TV1: Phần cứng PL (HLS ISP, Stream-to-Tensor, Vivado/Vitis, timing)
A11: TV2: Phần mềm PS và đo lường (Linux, VART zero-copy, đo độ trễ/năng lượng)
A12: TV3: AI và dữ liệu (RAW, twin, huấn luyện, bộ điều khiển)
A14: Giai đoạn
A15: GĐ1 Nền tảng, baseline, dữ liệu: tuần 1–14
... A19: GĐ5 Viết, nộp bài B, phát hành: tuần 57–65

Sheet Tong hop
A1: Tuần | B1: Thứ Hai | C1: TV1 — Phần cứng PL | D1: TV2 — PS, đo lường | E1: TV3 — AI, dữ liệu | F1: Đầu ra dự kiến của tuần (cả nhóm) | G1: TT TV1 | H1: TT TV2 | I1: TT TV3
A2: 1 | B2: 46300 | C2: Cài Vivado/Vitis/Vitis HLS 2022.2; học hls::stream, dataflow, AXI4-Stream (UG1399 ch. 1–4) | D2: Ghi SD image Vitis AI 3.0 cho KV260; SSH, xmutil; chạy mẫu Vitis AI Library | E2: Khảo sát ISP hướng tác vụ (AdaptiveISP, Mosleh 2020, ReconfigISP, GenISP, Dirty Pixels); dựng Docker Vitis AI 3.0 | F2: Môi trường chạy được; bảng khảo sát 15 bài | G2: =TV1!F2 -> Chưa bắt đầu | H2: =TV2!F2 -> Chưa bắt đầu | I2: =TV3!F2 -> Chưa bắt đầu
A3: 2 | B3: 46307 | C3: Build lại TRD DPU B4096 cho KV260 từ Vitis AI 3.0 | D3: Cắm IMX219 vào J9, nạp overlay camera có sẵn, media-ctl 1080p RAW10 | E3: Lấy YOLOX-nano ReLU từ Model Zoo, PTQ, biên dịch xmodel B4096 | F3: Ảnh RAW đầu tiên; xmodel 1 subgraph | G3: =TV1!F3 -> Chưa bắt đầu | H3: =TV2!F3 -> Chưa bắt đầu | I3: =TV3!F3 -> Chưa bắt đầu
A4: 3 | B4: 46314 | C4: Block design CSI-2 RX + Demosaic IP chuẩn theo thiết kế mở; đọc Vitis Vision ISP | D4: Ứng dụng BA1 bản đầu (V4L2 → OpenCV → VART, C++) | E4: Khảo sát dữ liệu RAW (LOD, PASCALRAW, ROD); viết unprocess COCO | F4: BA1 chạy trên ảnh tĩnh | G4: =TV1!F4 -> Chưa bắt đầu | H4: =TV2!F4 -> Chưa bắt đầu | I4: =TV3!F4 -> Chưa bắt đầu
A5: 4 | B5: 46321 | C5: Overlay DPU + CSI-2 (hoặc overlay có sẵn) — xdputil query | D5: YOLOX-nano chạy trên luồng camera; FPS thô | E5: Viết nháp mục Liên quan cho bài A và B | F5: G0 | G5: =TV1!F5 -> Chưa bắt đầu | H5: =TV2!F5 -> Chưa bắt đầu | I5: =TV3!F5 -> Chưa bắt đầu
A6: 5 | B6: 46328 | C6: isp_core: BLC + DPC/NR cửa sổ 5×5 phản xạ biên, testbench C++ | D6: Thiết kế hệ đo: AXI Timer + GPIO (cùng TV1), thư viện dấu thời gian | E6: Chụp ảnh tối + ảnh phẳng ở 4 mức analog gain | F6: Testbench BLC/DPC/NR chạy | G6: =TV1!F6 -> Chưa bắt đầu | H6: =TV2!F6 -> Chưa bắt đầu | I6: =TV3!F6 -> Chưa bắt đầu
A7: 6 | B7: 46335 | C7: Demosaic Malvar–He–Cutler 5×5 | D7: Mạch INA228 + MCU, firmware 1 kHz, đồng bộ GPIO | E7: isp_ref.py khớp bit cho BLC/DPC/NR; khớp mô hình nhiễu (a, b) | F7: Log công suất 12 V đầu tiên | G7: =TV1!F7 -> Chưa bắt đầu | H7: =TV2!F7 -> Chưa bắt đầu | I7: =TV3!F7 -> Chưa bắt đầu
A8: 7 | B8: 46342 | C8: WB + CCM + LUT tone + khối thống kê | D8: Hiệu chuẩn INA228 với tải và đồng hồ chuẩn | E8: isp_ref.py đủ chuỗi; make test so C++ ↔ NumPy | F8: Khớp bit 100 % trên khung tổng hợp | G8: =TV1!F8 -> Chưa bắt đầu | H8: =TV2!F8 -> Chưa bắt đầu | I8: =TV3!F8 -> Chưa bắt đầu
A9: 8 | B9: 46349 | C9: C-synth isp_top 1080p @150 MHz, II = 1, báo cáo tài nguyên | D9: LED glass-to-decision; kiểm tra độ lặp lại 5 lần | E9: Đưa make test vào CI; kịch bản thu KV-RAW-LUX (hộp sáng, lux kế) | F9: Báo cáo synth; p50 lặp lại ≤ 2 % | G9: =TV1!F9 -> Chưa bắt đầu | H9: =TV2!F9 -> Chưa bắt đầu | I9: =TV3!F9 -> Chưa bắt đầu
A10: 9 | B10: 46356 | C10: Co-sim RTL isp_top với 10 khung | D10: TN-A1: BA1 với 3 mô hình, 10 000 khung × 3 | E10: Thu D3 đợt 1 (trong nhà, 7 mức lux), RAW10 qua V4L2 | F10: Co-sim đạt | G10: =TV1!F10 -> Chưa bắt đầu | H10: =TV2!F10 -> Chưa bắt đầu | I10: =TV3!F10 -> Chưa bắt đầu
A11: 10 | B11: 46363 | C11: s2t_core: resize bilinear căn tâm pixel + lượng tử; so với cv2 | D11: BA2 (tiền xử lý NEON của Vitis AI Library) + TN-A1 | E11: D3 đợt 1 tiếp; công cụ giải nén RAW10 | F11: Sai khác S2T so với cv2 ≤ 2 LSB | G11: =TV1!F11 -> Chưa bắt đầu | H11: =TV2!F11 -> Chưa bắt đầu | I11: =TV3!F11 -> Chưa bắt đầu
A12: 11 | B12: 46370 | C12: Bộ ghi m_axi của S2T (burst), C-synth | D12: Phân tích TN-A1: phân rã độ trễ, bootstrap theo khối | E12: Gán nhãn D3 trên CVAT, 6 lớp; gán kép 10 % | F12: T-A1 sơ bộ cho BA1 | G12: =TV1!F12 -> Chưa bắt đầu | H12: =TV2!F12 -> Chưa bắt đầu | I12: =TV3!F12 -> Chưa bắt đầu
A13: 12 | B13: 46377 | C13: Bản m2m của S2T (đọc RGB từ DDR) cho BA3 + test | D13: Đo công suất nền; năng lượng BA1/BA2 | E13: Twin PyTorch v0 (float), so với isp_ref.py | F13: T-A2 sơ bộ cho BA1/BA2 | G13: =TV1!F13 -> Chưa bắt đầu | H13: =TV2!F13 -> Chưa bắt đầu | I13: =TV3!F13 -> Chưa bắt đầu
... A66: 65 | B66: 46748 | C66: Nghiệm thu, bàn giao board và tài liệu | D66: Nghiệm thu | E66: Nghiệm thu | F66: Kết thúc | G66: =TV1!F66 -> Chưa bắt đầu | H66: =TV2!F66 -> Chưa bắt đầu | I66: =TV3!F66 -> Chưa bắt đầu

Sheet Tien do
A1: Trạng thái | B1: TV1 | C1: TV2 | D1: TV3 | E1: Cả nhóm
A2: Chưa bắt đầu | B2: =COUNTIF(TV1!$F$2:$F$66,$A2) -> 65 | C2: =COUNTIF(TV2!$F$2:$F$66,$A2) -> 65 | D2: =COUNTIF(TV3!$F$2:$F$66,$A2) -> 65 | E2: =SUM(B2:D2) -> 195
A3: Đang làm | B3: =COUNTIF(TV1!$F$2:$F$66,$A3) -> 0 | C3: =COUNTIF(TV2!$F$2:$F$66,$A3) -> 0 | D3: =COUNTIF(TV3!$F$2:$F$66,$A3) -> 0 | E3: =SUM(B3:D3) -> 0
A4: Xong | B4: =COUNTIF(TV1!$F$2:$F$66,$A4) -> 0 | C4: =COUNTIF(TV2!$F$2:$F$66,$A4) -> 0 | D4: =COUNTIF(TV3!$F$2:$F$66,$A4) -> 0 | E4: =SUM(B4:D4) -> 0
A5: Trễ | B5: =COUNTIF(TV1!$F$2:$F$66,$A5) -> 0 | C5: =COUNTIF(TV2!$F$2:$F$66,$A5) -> 0 | D5: =COUNTIF(TV3!$F$2:$F$66,$A5) -> 0 | E5: =SUM(B5:D5) -> 0
A6: Bỏ/Chuyển | B6: =COUNTIF(TV1!$F$2:$F$66,$A6) -> 0 | C6: =COUNTIF(TV2!$F$2:$F$66,$A6) -> 0 | D6: =COUNTIF(TV3!$F$2:$F$66,$A6) -> 0 | E6: =SUM(B6:D6) -> 0
A7: Tổng số tuần | B7: =SUM(B2:B6) -> 65 | C7: =SUM(C2:C6) -> 65 | D7: =SUM(D2:D6) -> 65 | E7: =SUM(E2:E6) -> 195
A8: % tuần đã xong | B8: =IF(B7=0,0,B4/B7) -> 0 | C8: =IF(C7=0,0,C4/C7) -> 0 | D8: =IF(D7=0,0,D4/D7) -> 0 | E8: =IF(E7=0,0,E4/E7) -> 0

Sheet TV1
A1: Tuần | B1: Giai đoạn | C1: Thứ Hai | D1: Công việc của TV1 | E1: Mốc nhóm (cổng / nộp bài) | F1: Trạng thái | G1: Ghi chú
A2: 1 | B2: GĐ1 Nền tảng, baseline, dữ liệu | C2: 46300 | D2: Cài Vivado/Vitis/Vitis HLS 2022.2; học hls::stream, dataflow, AXI4-Stream (UG1399 ch. 1–4) | F2: Chưa bắt đầu
A3: 2 | B3: GĐ1 Nền tảng, baseline, dữ liệu | C3: 46307 | D3: Build lại TRD DPU B4096 cho KV260 từ Vitis AI 3.0 | F3: Chưa bắt đầu
A4: 3 | B4: GĐ1 Nền tảng, baseline, dữ liệu | C4: 46314 | D4: Block design CSI-2 RX + Demosaic IP chuẩn theo thiết kế mở; đọc Vitis Vision ISP | F4: Chưa bắt đầu
A5: 4 | B5: GĐ1 Nền tảng, baseline, dữ liệu | C5: 46321 | D5: Overlay DPU + CSI-2 (hoặc overlay có sẵn) — xdputil query | E5: G0 | F5: Chưa bắt đầu
A6: 5 | B6: GĐ1 Nền tảng, baseline, dữ liệu | C6: 46328 | D6: isp_core: BLC + DPC/NR cửa sổ 5×5 phản xạ biên, testbench C++ | F6: Chưa bắt đầu
A7: 6 | B7: GĐ1 Nền tảng, baseline, dữ liệu | C7: 46335 | D7: Demosaic Malvar–He–Cutler 5×5 | F7: Chưa bắt đầu
A8: 7 | B8: GĐ1 Nền tảng, baseline, dữ liệu | C8: 46342 | D8: WB + CCM + LUT tone + khối thống kê | F8: Chưa bắt đầu
A9: 8 | B9: GĐ1 Nền tảng, baseline, dữ liệu | C9: 46349 | D9: C-synth isp_top 1080p @150 MHz, II = 1, báo cáo tài nguyên | F9: Chưa bắt đầu
A10: 9 | B10: GĐ1 Nền tảng, baseline, dữ liệu | C10: 46356 | D10: Co-sim RTL isp_top với 10 khung | F10: Chưa bắt đầu
A11: 10 | B11: GĐ1 Nền tảng, baseline, dữ liệu | C11: 46363 | D11: s2t_core: resize bilinear căn tâm pixel + lượng tử; so với cv2 | F11: Chưa bắt đầu
A12: 11 | B12: GĐ1 Nền tảng, baseline, dữ liệu | C12: 46370 | D12: Bộ ghi m_axi của S2T (burst), C-synth | F12: Chưa bắt đầu
A13: 12 | B13: GĐ1 Nền tảng, baseline, dữ liệu | C13: 46377 | D13: Bản m2m của S2T (đọc RGB từ DDR) cho BA3 + test | F13: Chưa bắt đầu
A14: 13 | B14: GĐ1 Nền tảng, baseline, dữ liệu | C14: 46384 | D14: isp_top + s2t_top vào block design (chưa DPU), camera → ISP → VDMA | F14: Chưa bắt đầu
A15: 14 | B15: GĐ1 Nền tảng, baseline, dữ liệu | C15: 46391 | D15: Đọc thống kê ISP trên board (mùa thi — việc nhẹ) | E15: G1 | F15: Chưa bắt đầu
A16: 15 | B16: GĐ2 ISP + S2T trên PL, twin khớp bit | C16: 46398 | D16: Vitis link: DPU + isp_top + s2t_top + CSI-2 (link.cfg), build 1 (mùa thi) | F16: Chưa bắt đầu
A17: 16 | B17: GĐ2 ISP + S2T trên PL, twin khớp bit | C17: 46405 | D17: Sửa timing build 1, pblock cho ISP | F17: Chưa bắt đầu
A18: 17 | B18: GĐ2 ISP + S2T trên PL, twin khớp bit | C18: 46412 | D18: Build 2 đóng timing; device-tree overlay cho 2 kernel | F18: Chưa bắt đầu
A19: 18 | B19: GĐ2 ISP + S2T trên PL, twin khớp bit | C19: 46419 | D19: ISP chạy trên camera 1080p; hiệu chuẩn BLC, CCM từ bảng 24 ô | F19: Chưa bắt đầu
A20: 19 | B20: GĐ2 ISP + S2T trên PL, twin khớp bit | C20: 46426 | D20: Nghỉ Tết | F20: Chưa bắt đầu
A21: 20 | B21: GĐ2 ISP + S2T trên PL, twin khớp bit | C21: 46433 | D21: Kernel replay RAW từ DDR vào ISP (đo mAP trên HW) | F21: Chưa bắt đầu
A22: 21 | B22: GĐ2 ISP + S2T trên PL, twin khớp bit | C22: 46440 | D22: Khớp bit trên board: RAW replay → so với isp_ref.py | F22: Chưa bắt đầu
A23: 22 | B23: GĐ2 ISP + S2T trên PL, twin khớp bit | C23: 46447 | D23: Bắt đầu build DSE: DPU B3136/B2304 + ISP đầy đủ (chạy đêm) | F23: Chưa bắt đầu
A24: 23 | B24: GĐ2 ISP + S2T trên PL, twin khớp bit | C24: 46454 | D24: Build DSE với ISP tối thiểu | F24: Chưa bắt đầu
A25: 24 | B25: GĐ2 ISP + S2T trên PL, twin khớp bit | C25: 46461 | D25: Tối ưu S2T (burst); chuẩn bị biến thể HP/HPC (A5) | F25: Chưa bắt đầu
A26: 25 | B26: GĐ2 ISP + S2T trên PL, twin khớp bit | C26: 46468 | D26: Tài liệu hoá phần cứng (README, bản đồ thanh ghi) | F26: Chưa bắt đầu
A27: 26 | B27: GĐ2 ISP + S2T trên PL, twin khớp bit | C27: 46475 | D27: Demo G2; khoá bitstream v1.0 (ghi hash) | E27: G2 | F27: Chưa bắt đầu
A28: 27 | B28: GĐ3 Thí nghiệm, nộp bài A | C28: 46482 | D28: Triển khai BA3 (S2T m2m) trong overlay đã khoá | F28: Chưa bắt đầu
A29: 28 | B29: GĐ3 Thí nghiệm, nộp bài A | C29: 46489 | D29: TN-A4: APM cho BA1–BA3 | F29: Chưa bắt đầu
A30: 29 | B30: GĐ3 Thí nghiệm, nộp bài A | C30: 46496 | D30: TN-A4 cho P-TACo, A1 | F30: Chưa bắt đầu
A31: 30 | B31: GĐ3 Thí nghiệm, nộp bài A | C31: 46503 | D31: TN-A5: đo các điểm DSE đã build | F31: Chưa bắt đầu
A32: 31 | B32: GĐ3 Thí nghiệm, nộp bài A | C32: 46510 | D32: TN-A5 tiếp | F32: Chưa bắt đầu
A33: 32 | B33: GĐ3 Thí nghiệm, nộp bài A | C33: 46517 | D33: A5: HP vs HPC | F33: Chưa bắt đầu
A34: 33 | B34: GĐ3 Thí nghiệm, nộp bài A | C34: 46524 | D34: A6: độ phân giải × mô hình | F34: Chưa bắt đầu
A35: 34 | B35: GĐ3 Thí nghiệm, nộp bài A | C35: 46531 | D35: T-A3, F-A4 (Pareto) | F35: Chưa bắt đầu
A36: 35 | B36: GĐ3 Thí nghiệm, nộp bài A | C36: 46538 | D36: Viết mục Kiến trúc | F36: Chưa bắt đầu
A37: 36 | B37: GĐ3 Thí nghiệm, nộp bài A | C37: 46545 | D37: Viết mục DSE (mùa thi) | E37: G3 | F37: Chưa bắt đầu
A38: 37 | B38: GĐ3 Thí nghiệm, nộp bài A | C38: 46552 | D38: Bổ sung số liệu thiếu sau đọc chéo (mùa thi) | F38: Chưa bắt đầu
A39: 38 | B39: GĐ3 Thí nghiệm, nộp bài A | C39: 46559 | D39: Gói mã bài A, tag v1.0 (mùa thi) | F39: Chưa bắt đầu
A40: 39 | B40: GĐ3 Thí nghiệm, nộp bài A | C40: 46566 | D40: Tái lập từ kho sạch trên board thứ hai / SD mới | F40: Chưa bắt đầu
...

Sheet TV2
A1: Tuần | B1: Giai đoạn | C1: Thứ Hai | D1: Công việc của TV2 | E1: Mốc nhóm (cổng / nộp bài) | F1: Trạng thái | G1: Ghi chú
A2: 1 | B2: GĐ1 Nền tảng, baseline, dữ liệu | C2: 46300 | D2: Ghi SD image Vitis AI 3.0 cho KV260; SSH, xmutil; chạy mẫu Vitis AI Library | F2: Chưa bắt đầu
A3: 2 | B3: GĐ1 Nền tảng, baseline, dữ liệu | C3: 46307 | D3: Cắm IMX219 vào J9, nạp overlay camera có sẵn, media-ctl 1080p RAW10 | F3: Chưa bắt đầu
A4: 3 | B4: GĐ1 Nền tảng, baseline, dữ liệu | C4: 46314 | D4: Ứng dụng BA1 bản đầu (V4L2 → OpenCV → VART, C++) | F4: Chưa bắt đầu
A5: 4 | B5: GĐ1 Nền tảng, baseline, dữ liệu | C5: 46321 | D5: YOLOX-nano chạy trên luồng camera; FPS thô | E5: G0 | F5: Chưa bắt đầu
A6: 5 | B6: GĐ1 Nền tảng, baseline, dữ liệu | C6: 46328 | D6: Thiết kế hệ đo: AXI Timer + GPIO (cùng TV1), thư viện dấu thời gian | F6: Chưa bắt đầu
A7: 6 | B7: GĐ1 Nền tảng, baseline, dữ liệu | C7: 46335 | D7: Mạch INA228 + MCU, firmware 1 kHz, đồng bộ GPIO | F7: Chưa bắt đầu
A8: 7 | B8: GĐ1 Nền tảng, baseline, dữ liệu | C8: 46342 | D8: Hiệu chuẩn INA228 với tải và đồng hồ chuẩn | F8: Chưa bắt đầu
A9: 8 | B9: GĐ1 Nền tảng, baseline, dữ liệu | C9: 46349 | D9: LED glass-to-decision; kiểm tra độ lặp lại 5 lần | F9: Chưa bắt đầu
A10: 9 | B10: GĐ1 Nền tảng, baseline, dữ liệu | C10: 46356 | D10: TN-A1: BA1 với 3 mô hình, 10 000 khung × 3 | F10: Chưa bắt đầu
A11: 10 | B11: GĐ1 Nền tảng, baseline, dữ liệu | C11: 46363 | D11: BA2 (tiền xử lý NEON của Vitis AI Library) + TN-A1 | F11: Chưa bắt đầu
A12: 11 | B12: GĐ1 Nền tảng, baseline, dữ liệu | C12: 46370 | D12: Phân tích TN-A1: phân rã độ trễ, bootstrap theo khối | F12: Chưa bắt đầu
A13: 12 | B13: GĐ1 Nền tảng, baseline, dữ liệu | C13: 46377 | D13: Đo công suất nền; năng lượng BA1/BA2 | F13: Chưa bắt đầu
A14: 13 | B14: GĐ1 Nền tảng, baseline, dữ liệu | C14: 46384 | D14: Báo cáo RQ1: T-A1 + F-A2 sơ bộ | F14: Chưa bắt đầu
A15: 14 | B15: GĐ1 Nền tảng, baseline, dữ liệu | C15: 46391 | D15: Tổng hợp số liệu G1 (mùa thi) | E15: G1 | F15: Chưa bắt đầu
A16: 15 | B16: GĐ2 ISP + S2T trên PL, twin khớp bit | C16: 46398 | D16: Đọc mã VART: RunnerExt, TensorBuffer::data_phy(), fix_point (mùa thi) | F16: Chưa bắt đầu
A17: 16 | B17: GĐ2 ISP + S2T trên PL, twin khớp bit | C17: 46405 | D17: PoC zero-copy: UIO cho S2T, ghi dst = data_phy, execute_async | F17: Chưa bắt đầu
A18: 17 | B18: GĐ2 ISP + S2T trên PL, twin khớp bit | C18: 46412 | D18: Kiểm tra tensor PL = tensor CPU (0 sai khác) trên 500 khung | F18: Chưa bắt đầu
A19: 18 | B19: GĐ2 ISP + S2T trên PL, twin khớp bit | C19: 46419 | D19: Ứng dụng P-TACo 4 luồng, 3 bộ đệm | F19: Chưa bắt đầu
A20: 19 | B20: GĐ2 ISP + S2T trên PL, twin khớp bit | C20: 46426 | D20: Nghỉ Tết | F20: Chưa bắt đầu
A21: 20 | B21: GĐ2 ISP + S2T trên PL, twin khớp bit | C21: 46433 | D21: Đo độ trễ áp dụng phơi sáng/gain qua I2C (R9) | F21: Chưa bắt đầu
A22: 21 | B22: GĐ2 ISP + S2T trên PL, twin khớp bit | C22: 46440 | D22: Đảm bảo ≥ 30 FPS, gỡ nghẽn | F22: Chưa bắt đầu
A23: 22 | B23: GĐ2 ISP + S2T trên PL, twin khớp bit | C23: 46447 | D23: Hạ tầng thí nghiệm tự động (experiments/run_*.sh → CSV) | F23: Chưa bắt đầu
A24: 23 | B24: GĐ2 ISP + S2T trên PL, twin khớp bit | C24: 46454 | D24: TN-A1 lặp lại cho P-TACo sơ bộ | F24: Chưa bắt đầu
A25: 24 | B25: GĐ2 ISP + S2T trên PL, twin khớp bit | C25: 46461 | D25: Cấu hình AXI Performance Monitor trên cổng HP | F25: Chưa bắt đầu
A26: 25 | B26: GĐ2 ISP + S2T trên PL, twin khớp bit | C26: 46468 | D26: Kịch bản TN-A2–TN-A4 sẵn sàng | F26: Chưa bắt đầu
A27: 26 | B27: GĐ2 ISP + S2T trên PL, twin khớp bit | C27: 46475 | D27: Demo G2; khoá SD image | E27: G2 | F27: Chưa bắt đầu
A28: 27 | B28: GĐ3 Thí nghiệm, nộp bài A | C28: 46482 | D28: TN-A1 cho BA3; TN-A2 cho BA1, BA2 | F28: Chưa bắt đầu
A29: 28 | B29: GĐ3 Thí nghiệm, nộp bài A | C29: 46489 | D29: TN-A2 cho BA3, P-TACo; bắt đầu TN-A3 | F29: Chưa bắt đầu
A30: 29 | B30: GĐ3 Thí nghiệm, nộp bài A | C30: 46496 | D30: TN-A3: 5 × 60 s mỗi cấu hình | F30: Chưa bắt đầu
A31: 30 | B31: GĐ3 Thí nghiệm, nộp bài A | C31: 46503 | D31: TN-A3 xong; A1 (tắt zero-copy) | F31: Chưa bắt đầu
A32: 31 | B32: GĐ3 Thí nghiệm, nộp bài A | C32: 46510 | D32: A3 (N bộ đệm), A7 (ngắt/polling, isolcpus) | F32: Chưa bắt đầu
A33: 32 | B33: GĐ3 Thí nghiệm, nộp bài A | C33: 46517 | D33: A4: nhánh hiển thị bật/tắt | F33: Chưa bắt đầu
A34: 33 | B34: GĐ3 Thí nghiệm, nộp bài A | C34: 46524 | D34: Thống kê; make_tables.py sinh T-A1–T-A4 | F34: Chưa bắt đầu
A35: 34 | B35: GĐ3 Thí nghiệm, nộp bài A | C35: 46531 | D35: F-A2, F-A3, F-A5; viết mục Phương pháp đo | F35: Chưa bắt đầu
A36: 35 | B36: GĐ3 Thí nghiệm, nộp bài A | C36: 46538 | D36: Viết mục Phân tích pipeline, Kết quả | F36: Chưa bắt đầu
A37: 36 | B37: GĐ3 Thí nghiệm, nộp bài A | C37: 46545 | D37: Viết Giới thiệu, Liên quan; ghép bản thảo (mùa thi) | E37: G3 | F37: Chưa bắt đầu
A38: 37 | B38: GĐ3 Thí nghiệm, nộp bài A | C38: 46552 | D38: Sửa bản thảo (mùa thi) | F38: Chưa bắt đầu
A39: 38 | B39: GĐ3 Thí nghiệm, nộp bài A | C39: 46559 | D39: Hình cuối, định dạng theo tạp chí (mùa thi) | F39: Chưa bắt đầu
A40: 39 | B40: GĐ3 Thí nghiệm, nộp bài A | C40: 46566 | D40: Cover letter, highlights; kiểm ISSN với PL4 | F40: Chưa bắt đầu
...

Sheet TV3
A1: Tuần | B1: Giai đoạn | C1: Thứ Hai | D1: Công việc của TV3 | E1: Mốc nhóm (cổng / nộp bài) | F1: Trạng thái | G1: Ghi chú
A2: 1 | B2: GĐ1 Nền tảng, baseline, dữ liệu | C2: 46300 | D2: Khảo sát ISP hướng tác vụ (AdaptiveISP, Mosleh 2020, ReconfigISP, GenISP, Dirty Pixels); dựng Docker Vitis AI 3.0 | F2: Chưa bắt đầu
A3: 2 | B3: GĐ1 Nền tảng, baseline, dữ liệu | C3: 46307 | D3: Lấy YOLOX-nano ReLU từ Model Zoo, PTQ, biên dịch xmodel B4096 | F3: Chưa bắt đầu
A4: 3 | B4: GĐ1 Nền tảng, baseline, dữ liệu | C4: 46314 | D4: Khảo sát dữ liệu RAW (LOD, PASCALRAW, ROD); viết unprocess COCO | F4: Chưa bắt đầu
A5: 4 | B5: GĐ1 Nền tảng, baseline, dữ liệu | C5: 46321 | D5: Viết nháp mục Liên quan cho bài A và B | E5: G0 | F5: Chưa bắt đầu
A6: 5 | B6: GĐ1 Nền tảng, baseline, dữ liệu | C6: 46328 | D6: Chụp ảnh tối + ảnh phẳng ở 4 mức analog gain | F6: Chưa bắt đầu
A7: 6 | B7: GĐ1 Nền tảng, baseline, dữ liệu | C7: 46335 | D7: isp_ref.py khớp bit cho BLC/DPC/NR; khớp mô hình nhiễu (a, b) | F7: Chưa bắt đầu
A8: 7 | B8: GĐ1 Nền tảng, baseline, dữ liệu | C8: 46342 | D8: isp_ref.py đủ chuỗi; make test so C++ ↔ NumPy | F8: Chưa bắt đầu
A9: 8 | B9: GĐ1 Nền tảng, baseline, dữ liệu | C9: 46349 | D9: Đưa make test vào CI; kịch bản thu KV-RAW-LUX (hộp sáng, lux kế) | F9: Chưa bắt đầu
A10: 9 | B10: GĐ1 Nền tảng, baseline, dữ liệu | C10: 46356 | D10: Thu D3 đợt 1 (trong nhà, 7 mức lux), RAW10 qua V4L2 | F10: Chưa bắt đầu
A11: 10 | B11: GĐ1 Nền tảng, baseline, dữ liệu | C11: 46363 | D11: D3 đợt 1 tiếp; công cụ giải nén RAW10 | F11: Chưa bắt đầu
A12: 11 | B12: GĐ1 Nền tảng, baseline, dữ liệu | C12: 46370 | D12: Gán nhãn D3 trên CVAT, 6 lớp; gán kép 10 % | F12: Chưa bắt đầu
A13: 12 | B13: GĐ1 Nền tảng, baseline, dữ liệu | C13: 46377 | D13: Twin PyTorch v0 (float), so với isp_ref.py | F13: Chưa bắt đầu
A14: 13 | B14: GĐ1 Nền tảng, baseline, dữ liệu | C14: 46384 | D14: Twin v1 khớp bit (STE), test forward = isp_ref.py | F14: Chưa bắt đầu
A15: 14 | B15: GĐ1 Nền tảng, baseline, dữ liệu | C15: 46391 | D15: Unprocess COCO → D1 với nhiễu đã hiệu chuẩn | E15: G1 | F15: Chưa bắt đầu
A16: 15 | B16: GĐ2 ISP + S2T trên PL, twin khớp bit | C16: 46398 | D16: Twin trên D1: học ISP với detector đóng băng (kiểm tra tính đúng) | F16: Chưa bắt đầu
A17: 16 | B17: GĐ2 ISP + S2T trên PL, twin khớp bit | C17: 46405 | D17: B1, B2 trên D1: xử lý ảnh, huấn luyện detector | F17: Chưa bắt đầu
A18: 17 | B18: GĐ2 ISP + S2T trên PL, twin khớp bit | C18: 46412 | D18: B3: detector tinh chỉnh trên ảnh qua B2 | F18: Chưa bắt đầu
A19: 18 | B19: GĐ2 ISP + S2T trên PL, twin khớp bit | C19: 46419 | D19: Thu D3 đợt 2 (ngoài trời, ban đêm) | F19: Chưa bắt đầu
A20: 19 | B20: GĐ2 ISP + S2T trên PL, twin khớp bit | C20: 46426 | D20: Nghỉ Tết | F20: Chưa bắt đầu
A21: 20 | B21: GĐ2 ISP + S2T trên PL, twin khớp bit | C21: 46433 | D21: Gán nhãn D3 đợt 2; kiểm đếm ≥ 800 khung (R8) | F21: Chưa bắt đầu
A22: 21 | B22: GĐ2 ISP + S2T trên PL, twin khớp bit | C22: 46440 | D22: Twin v2: kiểm tra twin = HW replay (cùng TV1) | F22: Chưa bắt đầu
A23: 22 | B23: GĐ2 ISP + S2T trên PL, twin khớp bit | C23: 46447 | D23: Huấn luyện đồng thời ISP + detector (float) trên D1 + D3-train | F23: Chưa bắt đầu
A24: 23 | B24: GĐ2 ISP + S2T trên PL, twin khớp bit | C24: 46454 | D24: QAT bằng vai_q_pytorch với twin phía trước; xuất xmodel + thanh ghi ISP | F24: Chưa bắt đầu
A25: 24 | B25: GĐ2 ISP + S2T trên PL, twin khớp bit | C25: 46461 | D25: Tone nhận biết lượng tử (N-B2) | F25: Chưa bắt đầu
A26: 25 | B26: GĐ2 ISP + S2T trên PL, twin khớp bit | C26: 46468 | D26: Đánh giá sơ bộ P-static trên D3-val | F26: Chưa bắt đầu
A27: 26 | B27: GĐ2 ISP + S2T trên PL, twin khớp bit | C27: 46475 | D27: Báo cáo G2 phần twin | E27: G2 | F27: Chưa bắt đầu
A28: 27 | B28: GĐ3 Thí nghiệm, nộp bài A | C28: 46482 | D28: Huấn luyện P-static, seed 1 | F28: Chưa bắt đầu
A29: 28 | B29: GĐ3 Thí nghiệm, nộp bài A | C29: 46489 | D29: P-static seed 2, 3 | F29: Chưa bắt đầu
A30: 29 | B30: GĐ3 Thí nghiệm, nộp bài A | C30: 46496 | D30: B4: CMA-ES trên HW qua replay (lịch board buổi tối) | F30: Chưa bắt đầu
A31: 30 | B31: GĐ3 Thí nghiệm, nộp bài A | C31: 46503 | D31: Khoá tập test D3 (hash); B5 AdaptiveISP trên GPU | F31: Chưa bắt đầu
A32: 31 | B32: GĐ3 Thí nghiệm, nộp bài A | C32: 46510 | D32: B6: mạng tăng sáng lượng tử, biên dịch DPU | F32: Chưa bắt đầu
A33: 32 | B33: GĐ3 Thí nghiệm, nộp bài A | C33: 46517 | D33: B7: ISP tối thiểu + detector | F33: Chưa bắt đầu
A34: 33 | B34: GĐ3 Thí nghiệm, nộp bài A | C34: 46524 | D34: TN-B2: huấn luyện twin float vs khớp bit | F34: Chưa bắt đầu
A35: 34 | B35: GĐ3 Thí nghiệm, nộp bài A | C35: 46531 | D35: TN-B2: đo trên HW replay | F35: Chưa bắt đầu
A36: 35 | B36: GĐ3 Thí nghiệm, nộp bài A | C36: 46538 | D36: mAP P-TACo vs BA1 trên D3 (cho phản biện bài A) | F36: Chưa bắt đầu
A37: 36 | B37: GĐ3 Thí nghiệm, nộp bài A | C37: 46545 | D37: Đọc chéo bản thảo A (mùa thi) | E37: G3 | F37: Chưa bắt đầu
A38: 37 | B38: GĐ3 Thí nghiệm, nộp bài A | C38: 46552 | D38: B-A1–B-A6 chạy nền trên GPU | F38: Chưa bắt đầu
A39: 38 | B39: GĐ3 Thí nghiệm, nộp bài A | C39: 46559 | D39: B-A1–B-A6 tiếp | F39: Chưa bắt đầu
A40: 39 | B40: GĐ3 Thí nghiệm, nộp bài A | C40: 46566 | D40: Phân tích B-A1–B-A6 | F40: Chưa bắt đầu
...
